Workbook
Name Bosnia: Data!$M$4:$M$12
Name Country: Data!$M$3:$T$3
Name Croatia: Data!$O$4:$O$30
Name Czech_R.: Data!$N$4:$N$33
Name Poland: Data!$P$4:$P$8
Name Romania: Data!$Q$4:$Q$27
Name Serbia: Data!$R$4:$R$22
Name Slovakia: Data!$S$4:$S$44
Name Slovenia: Data!$T$4:$T$8

Sheet Data
G2: ACTUAL | H2: PLAN | I2: PLAN | J2: PLAN
B3: Data | D3: LINE | E3: SHOP | F3: Concatenate | G3: October YTD | H3: Nov 2022 | I3: Dec 2022 | J3: 2022 | M3: Austria
D4: Kgs put into the shop-Shop_A | E4: Paniglgasse | F4: Kgs put into the shop-Shop_APaniglgasse | G4: 3575 | H4: 300 | I4: 750 | J4: 6850 | M4: Paniglgasse
D5: Kgs put into the shop-Shop_B | E5: Paniglgasse | F5: Kgs put into the shop-Shop_BPaniglgasse | G5: 1890 | H5: 900 | I5: 600 | J5: 7250 | M5: Lerchenfelder
D6: Kgs put into the shop-Shoes_A | E6: Paniglgasse | F6: Kgs put into the shop-Shoes_APaniglgasse | G6: 312.5 | H6: 80 | I6: 160 | J6: 1520
D7: Kgs put into the shop-Shoes_B | E7: Paniglgasse | F7: Kgs put into the shop-Shoes_BPaniglgasse | G7: 0 | H7: 0 | I7: 0 | J7: 0
D8: Kgs put into the shop-HHR | E8: Paniglgasse | F8: Kgs put into the shop-HHRPaniglgasse | G8: 0 | H8: 0 | I8: 80 | J8: 800
D9: Kgs put into the shop-Mix_Summer | E9: Paniglgasse | F9: Kgs put into the shop-Mix_SummerPaniglgasse | G9: 0 | H9: 0 | I9: 0 | J9: 0
D10: Kgs put into the shop-Mix_Winter | E10: Paniglgasse | F10: Kgs put into the shop-Mix_WinterPaniglgasse | G10: 0 | H10: 0 | I10: 0 | J10: 0
D11: Kgs put into the shop-Handbag_A | E11: Paniglgasse | F11: Kgs put into the shop-Handbag_APaniglgasse | G11: 359 | H11: 40 | I11: 100 | J11: 1000
D12: Kgs put into the shop-Handbag_B | E12: Paniglgasse | F12: Kgs put into the shop-Handbag_BPaniglgasse | G12: 0 | H12: 0 | I12: 0 | J12: 0
D13: Kgs put into the shop-Things | E13: Paniglgasse | F13: Kgs put into the shop-ThingsPaniglgasse | G13: 39.5
D14: Turnover incl. VAT | E14: Paniglgasse | F14: Turnover incl. VATPaniglgasse | G14: 118687.03 | H14: 19000 | I14: 33800 | J14: 343300
D15: Income excl. VAT | E15: Paniglgasse | F15: Income excl. VATPaniglgasse | G15: 98905.858 | H15: 15833.333 | I15: 28166.667 | J15: 286083.33
D16: Cost of clothes put in the shop | E16: Paniglgasse | F16: Cost of clothes put in the shopPaniglgasse | G16: 23780.1 | H16: 3552 | I16: 5854 | J16: 57432
D17: Transport of clothes (international) | E17: Paniglgasse | F17: Transport of clothes (international)Paniglgasse | G17: 0 | H17: 400 | I17: 400 | J17: 4720
D18: Transport of clothes (local) | E18: Paniglgasse | F18: Transport of clothes (local)Paniglgasse | G18: 0 | H18: 0 | I18: 0 | J18: 0
D19: Customs brokers fees | E19: Paniglgasse | F19: Customs brokers feesPaniglgasse | G19: 0 | H19: 0 | I19: 0 | J19: 0
D20: Rent of the shop | E20: Paniglgasse | F20: Rent of the shopPaniglgasse | G20: 48594.134 | H20: 4952 | I20: 4952 | J20: 55706
D21: Electricity / heating / water | E21: Paniglgasse | F21: Electricity / heating / waterPaniglgasse | G21: 3242.44 | H21: 276 | I21: 55 | J21: 3088
D22: Maintenance, renovation | E22: Paniglgasse | F22: Maintenance, renovationPaniglgasse | G22: 3078.4 | H22: 0 | I22: 0 | J22: 9000
D23: Insurance | E23: Paniglgasse | F23: InsurancePaniglgasse | G23: 0 | H23: 0 | I23: 0 | J23: 0
D24: Acquisition of assets for buildings | E24: Paniglgasse | F24: Acquisition of assets for buildingsPaniglgasse | G24: 0 | H24: 0 | I24: 0 | J24: 2000
D25: Other (real estate fees, brokers fees, etc.) | E25: Paniglgasse | F25: Other (real estate fees, brokers fees, etc.)Paniglgasse | G25: 0 | H25: 0 | I25: 0 | J25: 0
... D59: Kgs put into the shop-Handbag_B | E59: Lerchenfelder | F59: Kgs put into the shop-Handbag_BLerchenfelder | G59: 0 | H59: 0 | I59: 0 | J59: 0
D60: Kgs put into the shop-Things | E60: Lerchenfelder | F60: Kgs put into the shop-ThingsLerchenfelder | G60: 5
D61: Turnover incl. VAT | E61: Lerchenfelder | F61: Turnover incl. VATLerchenfelder | G61: 54610 | H61: 0 | I61: 0 | J61: 0
D62: Income excl. VAT | E62: Lerchenfelder | F62: Income excl. VATLerchenfelder | G62: 45508.333 | H62: 0 | I62: 0 | J62: 0
D63: Cost of clothes put in the shop | E63: Lerchenfelder | F63: Cost of clothes put in the shopLerchenfelder | G63: 15273 | H63: 0 | I63: 0 | J63: 0
D64: Transport of clothes (international) | E64: Lerchenfelder | F64: Transport of clothes (international)Lerchenfelder | G64: 0 | H64: 0 | I64: 0 | J64: 0
D65: Transport of clothes (local) | E65: Lerchenfelder | F65: Transport of clothes (local)Lerchenfelder | G65: 0 | H65: 0 | I65: 0 | J65: 0
D66: Customs brokers fees | E66: Lerchenfelder | F66: Customs brokers feesLerchenfelder | G66: 0 | H66: 0 | I66: 0 | J66: 0
D67: Rent of the shop | E67: Lerchenfelder | F67: Rent of the shopLerchenfelder | G67: 4089.2 | H67: 0 | I67: 0 | J67: 0
D68: Electricity / heating / water | E68: Lerchenfelder | F68: Electricity / heating / waterLerchenfelder | G68: 0 | H68: 0 | I68: 0 | J68: 0
D69: Maintenance, renovation | E69: Lerchenfelder | F69: Maintenance, renovationLerchenfelder | G69: 0 | H69: 0 | I69: 0 | J69: 0
D70: Insurance | E70: Lerchenfelder | F70: InsuranceLerchenfelder | G70: 0 | H70: 0 | I70: 0 | J70: 0
D71: Acquisition of assets for buildings | E71: Lerchenfelder | F71: Acquisition of assets for buildingsLerchenfelder | G71: 0 | H71: 0 | I71: 0 | J71: 0
D72: Other (real estate fees, brokers fees, etc.) | E72: Lerchenfelder | F72: Other (real estate fees, brokers fees, etc.)Lerchenfelder | G72: 0 | H72: 0 | I72: 0 | J72: 0
... D97: Leasing of staff | E97: Lerchenfelder | F97: Leasing of staffLerchenfelder | G97: 0 | H97: 0 | I97: 0 | J97: 0

Sheet Data_Live
H2: BW | I2: BP | J2: BQ | K2: BR | V2: BW | W2: BP | X2: BQ | Y2: BR
C3: !!! | D3: Temporary employees - renamed to - Temporry employees | H3: BU | V3: BU
C4: !!! | H4: BO | Q4: Check operating result | V4: BO
H7: ACTUAL | I7: PLAN | J7: PLAN | K7: PLAN | R7: Operating result from WR | V7: ACTUAL | W7: PLAN | X7: PLAN | Y7: PLAN | AD7: Operating result Paste values | AI7: Check operating values
D8: Line | E8: SHOP | F8: Country | G8: Concatenate | H8: October YTD | I8: Nov 2022 | J8: Dec 2022 | K8: 2022 | M8: ACT | N8: BGT | R8: Line | S8: SHOP | T8: Country | U8: Concatenate | V8: October YTD | W8: Nov 2022 | X8: Dec 2022 | Y8: 2022 | AA8: ACT | AB8: BGT | AP8: SHOPS (List): | AQ8: Country | AS8: Country | AT8: File-path
C9: =VLOOKUP($F9,$AS:$AT,2,FALSE) -> [AT_WR_43_2022_SHOPS.xlsx] | D9: Kgs put into the shop-Shop_A | E9: =AP9 -> Paniglgasse | F9: =VLOOKUP($E9,$AP:$AQ,2,FALSE) -> AT | G9: =D9&E9 -> Kgs put into the shop-Shop_APaniglgasse | H9: =IFERROR(INDIRECT(CONCATENATE("'",$C9,$E9,"'","!",$H$2,$M9))+INDIRECT(CONCATENATE("'",$C9,$E9,"'","!",$H$3,$M9))+INDIRECT(CONCATENATE("'",$C9,$E9,"'","!",$H$4,$M9)),"") | I9: =IFERROR(IF(I$7="PLAN",INDIRECT(CONCATENATE("'",$C9,$E9,"'","!",$I$2,$N9)),INDIRECT(CONCATENATE("'",$C9,$E9,"'","!",$I$2,$M9))),"") | J9: =IFERROR(IF(J$7="PLAN",INDIRECT(CONCATENATE("'",$C9,$E9,"'","!",$J$2,$N9)),INDIRECT(CONCATENATE("'",$C9,$E9,"'","!",$J$2,$M9))),"") | K9: =IFERROR(IF(K$7="PLAN",INDIRECT(CONCATENATE("'",$C9,$E9,"'","!",$K$2,$N9)),INDIRECT(CONCATENATE("'",$C9,$E9,"'","!",$K$2,$M9))),"") | M9: 37 | N9: 283 | AP9: Paniglgasse | AQ9: AT
C10: =VLOOKUP($F10,$AS:$AT,2,FALSE) -> [AT_WR_43_2022_SHOPS.xlsx] | D10: Kgs put into the shop-Shop_B | E10: =E9 -> Paniglgasse | F10: =VLOOKUP($E10,$AP:$AQ,2,FALSE) -> AT | G10: =D10&E10 -> Kgs put into the shop-Shop_BPaniglgasse | H10: =IFERROR(INDIRECT(CONCATENATE("'",$C10,$E10,"'","!",$H$2,$M10))+INDIRECT(CONCATENATE("'",$C10,$E10,"'","!",$H$3,$M10))+INDIRECT(CONCATENATE("'",$C10,$E10,"'","!",$H$4,$M10)),"") | I10: =IFERROR(IF(I$7="PLAN",INDIRECT(CONCATENATE("'",$C10,$E10,"'","!",$I$2,$N10)),INDIRECT(CONCATENATE("'",$C10,$E10,"'","!",$I$2,$M10))),"") | J10: =IFERROR(IF(J$7="PLAN",INDIRECT(CONCATENATE("'",$C10,$E10,"'","!",$J$2,$N10)),INDIRECT(CONCATENATE("'",$C10,$E10,"'","!",$J$2,$M10))),"") | K10: =IFERROR(IF(K$7="PLAN",INDIRECT(CONCATENATE("'",$C10,$E10,"'","!",$K$2,$N10)),INDIRECT(CONCATENATE("'",$C10,$E10,"'","!",$K$2,$M10))),"") | M10: 38 | N10: 284 | AP10: Lerchenfelder | AQ10: AT | AS10: AT | AT10: [AT_WR_43_2022_SHOPS.xlsx]
C11: =VLOOKUP($F11,$AS:$AT,2,FALSE) -> [AT_WR_43_2022_SHOPS.xlsx] | D11: Kgs put into the shop-Shoes_A | E11: =E10 -> Paniglgasse | F11: =VLOOKUP($E11,$AP:$AQ,2,FALSE) -> AT | G11: =D11&E11 -> Kgs put into the shop-Shoes_APaniglgasse | H11: =IFERROR(INDIRECT(CONCATENATE("'",$C11,$E11,"'","!",$H$2,$M11))+INDIRECT(CONCATENATE("'",$C11,$E11,"'","!",$H$3,$M11))+INDIRECT(CONCATENATE("'",$C11,$E11,"'","!",$H$4,$M11)),"") | I11: =IFERROR(IF(I$7="PLAN",INDIRECT(CONCATENATE("'",$C11,$E11,"'","!",$I$2,$N11)),INDIRECT(CONCATENATE("'",$C11,$E11,"'","!",$I$2,$M11))),"") | J11: =IFERROR(IF(J$7="PLAN",INDIRECT(CONCATENATE("'",$C11,$E11,"'","!",$J$2,$N11)),INDIRECT(CONCATENATE("'",$C11,$E11,"'","!",$J$2,$M11))),"") | K11: =IFERROR(IF(K$7="PLAN",INDIRECT(CONCATENATE("'",$C11,$E11,"'","!",$K$2,$N11)),INDIRECT(CONCATENATE("'",$C11,$E11,"'","!",$K$2,$M11))),"") | M11: 40 | N11: 285
C12: =VLOOKUP($F12,$AS:$AT,2,FALSE) -> [AT_WR_43_2022_SHOPS.xlsx] | D12: Kgs put into the shop-Shoes_B | E12: =E11 -> Paniglgasse | F12: =VLOOKUP($E12,$AP:$AQ,2,FALSE) -> AT | G12: =D12&E12 -> Kgs put into the shop-Shoes_BPaniglgasse | H12: =IFERROR(INDIRECT(CONCATENATE("'",$C12,$E12,"'","!",$H$2,$M12))+INDIRECT(CONCATENATE("'",$C12,$E12,"'","!",$H$3,$M12))+INDIRECT(CONCATENATE("'",$C12,$E12,"'","!",$H$4,$M12)),"") | I12: =IFERROR(IF(I$7="PLAN",INDIRECT(CONCATENATE("'",$C12,$E12,"'","!",$I$2,$N12)),INDIRECT(CONCATENATE("'",$C12,$E12,"'","!",$I$2,$M12))),"") | J12: =IFERROR(IF(J$7="PLAN",INDIRECT(CONCATENATE("'",$C12,$E12,"'","!",$J$2,$N12)),INDIRECT(CONCATENATE("'",$C12,$E12,"'","!",$J$2,$M12))),"") | K12: =IFERROR(IF(K$7="PLAN",INDIRECT(CONCATENATE("'",$C12,$E12,"'","!",$K$2,$N12)),INDIRECT(CONCATENATE("'",$C12,$E12,"'","!",$K$2,$M12))),"") | M12: 41 | N12: 286
C13: =VLOOKUP($F13,$AS:$AT,2,FALSE) -> [AT_WR_43_2022_SHOPS.xlsx] | D13: Kgs put into the shop-HHR | E13: =E12 -> Paniglgasse | F13: =VLOOKUP($E13,$AP:$AQ,2,FALSE) -> AT | G13: =D13&E13 -> Kgs put into the shop-HHRPaniglgasse | H13: =IFERROR(INDIRECT(CONCATENATE("'",$C13,$E13,"'","!",$H$2,$M13))+INDIRECT(CONCATENATE("'",$C13,$E13,"'","!",$H$3,$M13))+INDIRECT(CONCATENATE("'",$C13,$E13,"'","!",$H$4,$M13)),"") | I13: =IFERROR(IF(I$7="PLAN",INDIRECT(CONCATENATE("'",$C13,$E13,"'","!",$I$2,$N13)),INDIRECT(CONCATENATE("'",$C13,$E13,"'","!",$I$2,$M13))),"") | J13: =IFERROR(IF(J$7="PLAN",INDIRECT(CONCATENATE("'",$C13,$E13,"'","!",$J$2,$N13)),INDIRECT(CONCATENATE("'",$C13,$E13,"'","!",$J$2,$M13))),"") | K13: =IFERROR(IF(K$7="PLAN",INDIRECT(CONCATENATE("'",$C13,$E13,"'","!",$K$2,$N13)),INDIRECT(CONCATENATE("'",$C13,$E13,"'","!",$K$2,$M13))),"") | M13: 39 | N13: 287
C14: =VLOOKUP($F14,$AS:$AT,2,FALSE) -> [AT_WR_43_2022_SHOPS.xlsx] | D14: Kgs put into the shop-Mix_Summer | E14: =E13 -> Paniglgasse | F14: =VLOOKUP($E14,$AP:$AQ,2,FALSE) -> AT | G14: =D14&E14 -> Kgs put into the shop-Mix_SummerPaniglgasse | H14: =IFERROR(INDIRECT(CONCATENATE("'",$C14,$E14,"'","!",$H$2,$M14))+INDIRECT(CONCATENATE("'",$C14,$E14,"'","!",$H$3,$M14))+INDIRECT(CONCATENATE("'",$C14,$E14,"'","!",$H$4,$M14)),"") | I14: =IFERROR(IF(I$7="PLAN",INDIRECT(CONCATENATE("'",$C14,$E14,"'","!",$I$2,$N14)),INDIRECT(CONCATENATE("'",$C14,$E14,"'","!",$I$2,$M14))),"") | J14: =IFERROR(IF(J$7="PLAN",INDIRECT(CONCATENATE("'",$C14,$E14,"'","!",$J$2,$N14)),INDIRECT(CONCATENATE("'",$C14,$E14,"'","!",$J$2,$M14))),"") | K14: =IFERROR(IF(K$7="PLAN",INDIRECT(CONCATENATE("'",$C14,$E14,"'","!",$K$2,$N14)),INDIRECT(CONCATENATE("'",$C14,$E14,"'","!",$K$2,$M14))),"") | M14: 42 | N14: 288
C15: =VLOOKUP($F15,$AS:$AT,2,FALSE) -> [AT_WR_43_2022_SHOPS.xlsx] | D15: Kgs put into the shop-Mix_Winter | E15: =E14 -> Paniglgasse | F15: =VLOOKUP($E15,$AP:$AQ,2,FALSE) -> AT | G15: =D15&E15 -> Kgs put into the shop-Mix_WinterPaniglgasse | H15: =IFERROR(INDIRECT(CONCATENATE("'",$C15,$E15,"'","!",$H$2,$M15))+INDIRECT(CONCATENATE("'",$C15,$E15,"'","!",$H$3,$M15))+INDIRECT(CONCATENATE("'",$C15,$E15,"'","!",$H$4,$M15)),"") | I15: =IFERROR(IF(I$7="PLAN",INDIRECT(CONCATENATE("'",$C15,$E15,"'","!",$I$2,$N15)),INDIRECT(CONCATENATE("'",$C15,$E15,"'","!",$I$2,$M15))),"") | J15: =IFERROR(IF(J$7="PLAN",INDIRECT(CONCATENATE("'",$C15,$E15,"'","!",$J$2,$N15)),INDIRECT(CONCATENATE("'",$C15,$E15,"'","!",$J$2,$M15))),"") | K15: =IFERROR(IF(K$7="PLAN",INDIRECT(CONCATENATE("'",$C15,$E15,"'","!",$K$2,$N15)),INDIRECT(CONCATENATE("'",$C15,$E15,"'","!",$K$2,$M15))),"") | M15: 43 | N15: 289
C16: =VLOOKUP($F16,$AS:$AT,2,FALSE) -> [AT_WR_43_2022_SHOPS.xlsx] | D16: Kgs put into the shop-Handbag_A | E16: =E15 -> Paniglgasse | F16: =VLOOKUP($E16,$AP:$AQ,2,FALSE) -> AT | G16: =D16&E16 -> Kgs put into the shop-Handbag_APaniglgasse | H16: =IFERROR(INDIRECT(CONCATENATE("'",$C16,$E16,"'","!",$H$2,$M16))+INDIRECT(CONCATENATE("'",$C16,$E16,"'","!",$H$3,$M16))+INDIRECT(CONCATENATE("'",$C16,$E16,"'","!",$H$4,$M16)),"") | I16: =IFERROR(IF(I$7="PLAN",INDIRECT(CONCATENATE("'",$C16,$E16,"'","!",$I$2,$N16)),INDIRECT(CONCATENATE("'",$C16,$E16,"'","!",$I$2,$M16))),"") | J16: =IFERROR(IF(J$7="PLAN",INDIRECT(CONCATENATE("'",$C16,$E16,"'","!",$J$2,$N16)),INDIRECT(CONCATENATE("'",$C16,$E16,"'","!",$J$2,$M16))),"") | K16: =IFERROR(IF(K$7="PLAN",INDIRECT(CONCATENATE("'",$C16,$E16,"'","!",$K$2,$N16)),INDIRECT(CONCATENATE("'",$C16,$E16,"'","!",$K$2,$M16))),"") | M16: 44 | N16: 290
C17: =VLOOKUP($F17,$AS:$AT,2,FALSE) -> [AT_WR_43_2022_SHOPS.xlsx] | D17: Kgs put into the shop-Handbag_B | E17: =E16 -> Paniglgasse | F17: =VLOOKUP($E17,$AP:$AQ,2,FALSE) -> AT | G17: =D17&E17 -> Kgs put into the shop-Handbag_BPaniglgasse | H17: =IFERROR(INDIRECT(CONCATENATE("'",$C17,$E17,"'","!",$H$2,$M17))+INDIRECT(CONCATENATE("'",$C17,$E17,"'","!",$H$3,$M17))+INDIRECT(CONCATENATE("'",$C17,$E17,"'","!",$H$4,$M17)),"") | I17: =IFERROR(IF(I$7="PLAN",INDIRECT(CONCATENATE("'",$C17,$E17,"'","!",$I$2,$N17)),INDIRECT(CONCATENATE("'",$C17,$E17,"'","!",$I$2,$M17))),"") | J17: =IFERROR(IF(J$7="PLAN",INDIRECT(CONCATENATE("'",$C17,$E17,"'","!",$J$2,$N17)),INDIRECT(CONCATENATE("'",$C17,$E17,"'","!",$J$2,$M17))),"") | K17: =IFERROR(IF(K$7="PLAN",INDIRECT(CONCATENATE("'",$C17,$E17,"'","!",$K$2,$N17)),INDIRECT(CONCATENATE("'",$C17,$E17,"'","!",$K$2,$M17))),"") | M17: 45 | N17: 291
C18: =VLOOKUP($F18,$AS:$AT,2,FALSE) -> [AT_WR_43_2022_SHOPS.xlsx] | D18: Kgs put into the shop-Things | E18: =E17 -> Paniglgasse | F18: =VLOOKUP($E18,$AP:$AQ,2,FALSE) -> AT | G18: =D18&E18 -> Kgs put into the shop-ThingsPaniglgasse | H18: =IFERROR(INDIRECT(CONCATENATE("'",$C18,$E18,"'","!",$H$2,$M18))+INDIRECT(CONCATENATE("'",$C18,$E18,"'","!",$H$3,$M18))+INDIRECT(CONCATENATE("'",$C18,$E18,"'","!",$H$4,$M18)),"") | I18: =IFERROR(IF(I$7="PLAN",INDIRECT(CONCATENATE("'",$C18,$E18,"'","!",$I$2,$N18)),INDIRECT(CONCATENATE("'",$C18,$E18,"'","!",$I$2,$M18))),"") | J18: =IFERROR(IF(J$7="PLAN",INDIRECT(CONCATENATE("'",$C18,$E18,"'","!",$J$2,$N18)),INDIRECT(CONCATENATE("'",$C18,$E18,"'","!",$J$2,$M18))),"") | K18: =IFERROR(IF(K$7="PLAN",INDIRECT(CONCATENATE("'",$C18,$E18,"'","!",$K$2,$N18)),INDIRECT(CONCATENATE("'",$C18,$E18,"'","!",$K$2,$M18))),"") | M18: 46
C19: =VLOOKUP($F19,$AS:$AT,2,FALSE) -> [AT_WR_43_2022_SHOPS.xlsx] | D19: Turnover incl. VAT | E19: =E18 -> Paniglgasse | F19: =VLOOKUP($E19,$AP:$AQ,2,FALSE) -> AT | G19: =D19&E19 -> Turnover incl. VATPaniglgasse | H19: =IFERROR(INDIRECT(CONCATENATE("'",$C19,$E19,"'","!",$H$2,$M19))+INDIRECT(CONCATENATE("'",$C19,$E19,"'","!",$H$3,$M19))+INDIRECT(CONCATENATE("'",$C19,$E19,"'","!",$H$4,$M19)),"") | I19: =IFERROR(IF(I$7="PLAN",INDIRECT(CONCATENATE("'",$C19,$E19,"'","!",$I$2,$N19)),INDIRECT(CONCATENATE("'",$C19,$E19,"'","!",$I$2,$M19))),"") | J19: =IFERROR(IF(J$7="PLAN",INDIRECT(CONCATENATE("'",$C19,$E19,"'","!",$J$2,$N19)),INDIRECT(CONCATENATE("'",$C19,$E19,"'","!",$J$2,$M19))),"") | K19: =IFERROR(IF(K$7="PLAN",INDIRECT(CONCATENATE("'",$C19,$E19,"'","!",$K$2,$N19)),INDIRECT(CONCATENATE("'",$C19,$E19,"'","!",$K$2,$M19))),"") | M19: 73 | N19: 302
C20: =VLOOKUP($F20,$AS:$AT,2,FALSE) -> [AT_WR_43_2022_SHOPS.xlsx] | D20: Income excl. VAT | E20: =E19 -> Paniglgasse | F20: =VLOOKUP($E20,$AP:$AQ,2,FALSE) -> AT | G20: =D20&E20 -> Income excl. VATPaniglgasse | H20: =IFERROR(INDIRECT(CONCATENATE("'",$C20,$E20,"'","!",$H$2,$M20))+INDIRECT(CONCATENATE("'",$C20,$E20,"'","!",$H$3,$M20))+INDIRECT(CONCATENATE("'",$C20,$E20,"'","!",$H$4,$M20)),"") | I20: =IFERROR(IF(I$7="PLAN",INDIRECT(CONCATENATE("'",$C20,$E20,"'","!",$I$2,$N20)),INDIRECT(CONCATENATE("'",$C20,$E20,"'","!",$I$2,$M20))),"") | J20: =IFERROR(IF(J$7="PLAN",INDIRECT(CONCATENATE("'",$C20,$E20,"'","!",$J$2,$N20)),INDIRECT(CONCATENATE("'",$C20,$E20,"'","!",$J$2,$M20))),"") | K20: =IFERROR(IF(K$7="PLAN",INDIRECT(CONCATENATE("'",$C20,$E20,"'","!",$K$2,$N20)),INDIRECT(CONCATENATE("'",$C20,$E20,"'","!",$K$2,$M20))),"") | M20: 74 | N20: 303
C21: =VLOOKUP($F21,$AS:$AT,2,FALSE) -> [AT_WR_43_2022_SHOPS.xlsx] | D21: Cost of clothes put in the shop | E21: =E20 -> Paniglgasse | F21: =VLOOKUP($E21,$AP:$AQ,2,FALSE) -> AT | G21: =D21&E21 -> Cost of clothes put in the shopPaniglgasse | H21: =IFERROR(INDIRECT(CONCATENATE("'",$C21,$E21,"'","!",$H$2,$M21))+INDIRECT(CONCATENATE("'",$C21,$E21,"'","!",$H$3,$M21))+INDIRECT(CONCATENATE("'",$C21,$E21,"'","!",$H$4,$M21)),"") | I21: =IFERROR(IF(I$7="PLAN",INDIRECT(CONCATENATE("'",$C21,$E21,"'","!",$I$2,$N21)),INDIRECT(CONCATENATE("'",$C21,$E21,"'","!",$I$2,$M21))),"") | J21: =IFERROR(IF(J$7="PLAN",INDIRECT(CONCATENATE("'",$C21,$E21,"'","!",$J$2,$N21)),INDIRECT(CONCATENATE("'",$C21,$E21,"'","!",$J$2,$M21))),"") | K21: =IFERROR(IF(K$7="PLAN",INDIRECT(CONCATENATE("'",$C21,$E21,"'","!",$K$2,$N21)),INDIRECT(CONCATENATE("'",$C21,$E21,"'","!",$K$2,$M21))),"") | M21: 82 | N21: 311
C22: =VLOOKUP($F22,$AS:$AT,2,FALSE) -> [AT_WR_43_2022_SHOPS.xlsx] | D22: Transport of clothes (international) | E22: =E21 -> Paniglgasse | F22: =VLOOKUP($E22,$AP:$AQ,2,FALSE) -> AT | G22: =D22&E22 -> Transport of clothes (international)Paniglgasse | H22: =IFERROR(INDIRECT(CONCATENATE("'",$C22,$E22,"'","!",$H$2,$M22))+INDIRECT(CONCATENATE("'",$C22,$E22,"'","!",$H$3,$M22))+INDIRECT(CONCATENATE("'",$C22,$E22,"'","!",$H$4,$M22)),"") | I22: =IFERROR(IF(I$7="PLAN",INDIRECT(CONCATENATE("'",$C22,$E22,"'","!",$I$2,$N22)),INDIRECT(CONCATENATE("'",$C22,$E22,"'","!",$I$2,$M22))),"") | J22: =IFERROR(IF(J$7="PLAN",INDIRECT(CONCATENATE("'",$C22,$E22,"'","!",$J$2,$N22)),INDIRECT(CONCATENATE("'",$C22,$E22,"'","!",$J$2,$M22))),"") | K22: =IFERROR(IF(K$7="PLAN",INDIRECT(CONCATENATE("'",$C22,$E22,"'","!",$K$2,$N22)),INDIRECT(CONCATENATE("'",$C22,$E22,"'","!",$K$2,$M22))),"") | M22: 83 | N22: 312
C23: =VLOOKUP($F23,$AS:$AT,2,FALSE) -> [AT_WR_43_2022_SHOPS.xlsx] | D23: Transport of clothes (local) | E23: =E22 -> Paniglgasse | F23: =VLOOKUP($E23,$AP:$AQ,2,FALSE) -> AT | G23: =D23&E23 -> Transport of clothes (local)Paniglgasse | H23: =IFERROR(INDIRECT(CONCATENATE("'",$C23,$E23,"'","!",$H$2,$M23))+INDIRECT(CONCATENATE("'",$C23,$E23,"'","!",$H$3,$M23))+INDIRECT(CONCATENATE("'",$C23,$E23,"'","!",$H$4,$M23)),"") | I23: =IFERROR(IF(I$7="PLAN",INDIRECT(CONCATENATE("'",$C23,$E23,"'","!",$I$2,$N23)),INDIRECT(CONCATENATE("'",$C23,$E23,"'","!",$I$2,$M23))),"") | J23: =IFERROR(IF(J$7="PLAN",INDIRECT(CONCATENATE("'",$C23,$E23,"'","!",$J$2,$N23)),INDIRECT(CONCATENATE("'",$C23,$E23,"'","!",$J$2,$M23))),"") | K23: =IFERROR(IF(K$7="PLAN",INDIRECT(CONCATENATE("'",$C23,$E23,"'","!",$K$2,$N23)),INDIRECT(CONCATENATE("'",$C23,$E23,"'","!",$K$2,$M23))),"") | M23: 84 | N23: 313
C24: =VLOOKUP($F24,$AS:$AT,2,FALSE) -> [AT_WR_43_2022_SHOPS.xlsx] | D24: Customs brokers fees | E24: =E23 -> Paniglgasse | F24: =VLOOKUP($E24,$AP:$AQ,2,FALSE) -> AT | G24: =D24&E24 -> Customs brokers feesPaniglgasse | H24: =IFERROR(INDIRECT(CONCATENATE("'",$C24,$E24,"'","!",$H$2,$M24))+INDIRECT(CONCATENATE("'",$C24,$E24,"'","!",$H$3,$M24))+INDIRECT(CONCATENATE("'",$C24,$E24,"'","!",$H$4,$M24)),"") | I24: =IFERROR(IF(I$7="PLAN",INDIRECT(CONCATENATE("'",$C24,$E24,"'","!",$I$2,$N24)),INDIRECT(CONCATENATE("'",$C24,$E24,"'","!",$I$2,$M24))),"") | J24: =IFERROR(IF(J$7="PLAN",INDIRECT(CONCATENATE("'",$C24,$E24,"'","!",$J$2,$N24)),INDIRECT(CONCATENATE("'",$C24,$E24,"'","!",$J$2,$M24))),"") | K24: =IFERROR(IF(K$7="PLAN",INDIRECT(CONCATENATE("'",$C24,$E24,"'","!",$K$2,$N24)),INDIRECT(CONCATENATE("'",$C24,$E24,"'","!",$K$2,$M24))),"") | M24: 85 | N24: 314
C25: =VLOOKUP($F25,$AS:$AT,2,FALSE) -> [AT_WR_43_2022_SHOPS.xlsx] | D25: Rent of the shop | E25: =E24 -> Paniglgasse | F25: =VLOOKUP($E25,$AP:$AQ,2,FALSE) -> AT | G25: =D25&E25 -> Rent of the shopPaniglgasse | H25: =IFERROR(INDIRECT(CONCATENATE("'",$C25,$E25,"'","!",$H$2,$M25))+INDIRECT(CONCATENATE("'",$C25,$E25,"'","!",$H$3,$M25))+INDIRECT(CONCATENATE("'",$C25,$E25,"'","!",$H$4,$M25)),"") | I25: =IFERROR(IF(I$7="PLAN",INDIRECT(CONCATENATE("'",$C25,$E25,"'","!",$I$2,$N25)),INDIRECT(CONCATENATE("'",$C25,$E25,"'","!",$I$2,$M25))),"") | J25: =IFERROR(IF(J$7="PLAN",INDIRECT(CONCATENATE("'",$C25,$E25,"'","!",$J$2,$N25)),INDIRECT(CONCATENATE("'",$C25,$E25,"'","!",$J$2,$M25))),"") | K25: =IFERROR(IF(K$7="PLAN",INDIRECT(CONCATENATE("'",$C25,$E25,"'","!",$K$2,$N25)),INDIRECT(CONCATENATE("'",$C25,$E25,"'","!",$K$2,$M25))),"") | M25: 88 | N25: 317
C26: =VLOOKUP($F26,$AS:$AT,2,FALSE) -> [AT_WR_43_2022_SHOPS.xlsx] | D26: Electricity / heating / water | E26: =E25 -> Paniglgasse | F26: =VLOOKUP($E26,$AP:$AQ,2,FALSE) -> AT | G26: =D26&E26 -> Electricity / heating / waterPaniglgasse | H26: =IFERROR(INDIRECT(CONCATENATE("'",$C26,$E26,"'","!",$H$2,$M26))+INDIRECT(CONCATENATE("'",$C26,$E26,"'","!",$H$3,$M26))+INDIRECT(CONCATENATE("'",$C26,$E26,"'","!",$H$4,$M26)),"") | I26: =IFERROR(IF(I$7="PLAN",INDIRECT(CONCATENATE("'",$C26,$E26,"'","!",$I$2,$N26)),INDIRECT(CONCATENATE("'",$C26,$E26,"'","!",$I$2,$M26))),"") | J26: =IFERROR(IF(J$7="PLAN",INDIRECT(CONCATENATE("'",$C26,$E26,"'","!",$J$2,$N26)),INDIRECT(CONCATENATE("'",$C26,$E26,"'","!",$J$2,$M26))),"") | K26: =IFERROR(IF(K$7="PLAN",INDIRECT(CONCATENATE("'",$C26,$E26,"'","!",$K$2,$N26)),INDIRECT(CONCATENATE("'",$C26,$E26,"'","!",$K$2,$M26))),"") | M26: 89 | N26: 318
C27: =VLOOKUP($F27,$AS:$AT,2,FALSE) -> [AT_WR_43_2022_SHOPS.xlsx] | D27: Maintenance, renovation | E27: =E26 -> Paniglgasse | F27: =VLOOKUP($E27,$AP:$AQ,2,FALSE) -> AT | G27: =D27&E27 -> Maintenance, renovationPaniglgasse | H27: =IFERROR(INDIRECT(CONCATENATE("'",$C27,$E27,"'","!",$H$2,$M27))+INDIRECT(CONCATENATE("'",$C27,$E27,"'","!",$H$3,$M27))+INDIRECT(CONCATENATE("'",$C27,$E27,"'","!",$H$4,$M27)),"") | I27: =IFERROR(IF(I$7="PLAN",INDIRECT(CONCATENATE("'",$C27,$E27,"'","!",$I$2,$N27)),INDIRECT(CONCATENATE("'",$C27,$E27,"'","!",$I$2,$M27))),"") | J27: =IFERROR(IF(J$7="PLAN",INDIRECT(CONCATENATE("'",$C27,$E27,"'","!",$J$2,$N27)),INDIRECT(CONCATENATE("'",$C27,$E27,"'","!",$J$2,$M27))),"") | K27: =IFERROR(IF(K$7="PLAN",INDIRECT(CONCATENATE("'",$C27,$E27,"'","!",$K$2,$N27)),INDIRECT(CONCATENATE("'",$C27,$E27,"'","!",$K$2,$M27))),"") | M27: 90 | N27: 319
C28: =VLOOKUP($F28,$AS:$AT,2,FALSE) -> [AT_WR_43_2022_SHOPS.xlsx] | D28: Insurance | E28: =E27 -> Paniglgasse | F28: =VLOOKUP($E28,$AP:$AQ,2,FALSE) -> AT | G28: =D28&E28 -> InsurancePaniglgasse | H28: =IFERROR(INDIRECT(CONCATENATE("'",$C28,$E28,"'","!",$H$2,$M28))+INDIRECT(CONCATENATE("'",$C28,$E28,"'","!",$H$3,$M28))+INDIRECT(CONCATENATE("'",$C28,$E28,"'","!",$H$4,$M28)),"") | I28: =IFERROR(IF(I$7="PLAN",INDIRECT(CONCATENATE("'",$C28,$E28,"'","!",$I$2,$N28)),INDIRECT(CONCATENATE("'",$C28,$E28,"'","!",$I$2,$M28))),"") | J28: =IFERROR(IF(J$7="PLAN",INDIRECT(CONCATENATE("'",$C28,$E28,"'","!",$J$2,$N28)),INDIRECT(CONCATENATE("'",$C28,$E28,"'","!",$J$2,$M28))),"") | K28: =IFERROR(IF(K$7="PLAN",INDIRECT(CONCATENATE("'",$C28,$E28,"'","!",$K$2,$N28)),INDIRECT(CONCATENATE("'",$C28,$E28,"'","!",$K$2,$M28))),"") | M28: 91 | N28: 320
C29: =VLOOKUP($F29,$AS:$AT,2,FALSE) -> [AT_WR_43_2022_SHOPS.xlsx] | D29: Acquisition of assets for buildings | E29: =E28 -> Paniglgasse | F29: =VLOOKUP($E29,$AP:$AQ,2,FALSE) -> AT | G29: =D29&E29 -> Acquisition of assets for buildingsPaniglgasse | H29: =IFERROR(INDIRECT(CONCATENATE("'",$C29,$E29,"'","!",$H$2,$M29))+INDIRECT(CONCATENATE("'",$C29,$E29,"'","!",$H$3,$M29))+INDIRECT(CONCATENATE("'",$C29,$E29,"'","!",$H$4,$M29)),"") | I29: =IFERROR(IF(I$7="PLAN",INDIRECT(CONCATENATE("'",$C29,$E29,"'","!",$I$2,$N29)),INDIRECT(CONCATENATE("'",$C29,$E29,"'","!",$I$2,$M29))),"") | J29: =IFERROR(IF(J$7="PLAN",INDIRECT(CONCATENATE("'",$C29,$E29,"'","!",$J$2,$N29)),INDIRECT(CONCATENATE("'",$C29,$E29,"'","!",$J$2,$M29))),"") | K29: =IFERROR(IF(K$7="PLAN",INDIRECT(CONCATENATE("'",$C29,$E29,"'","!",$K$2,$N29)),INDIRECT(CONCATENATE("'",$C29,$E29,"'","!",$K$2,$M29))),"") | M29: 92 | N29: 321
C30: =VLOOKUP($F30,$AS:$AT,2,FALSE) -> [AT_WR_43_2022_SHOPS.xlsx] | D30: Other (real estate fees, brokers fees, etc.) | E30: =E29 -> Paniglgasse | F30: =VLOOKUP($E30,$AP:$AQ,2,FALSE) -> AT | G30: =D30&E30 -> Other (real estate fees, brokers fees, etc.)Paniglgasse | H30: =IFERROR(INDIRECT(CONCATENATE("'",$C30,$E30,"'","!",$H$2,$M30))+INDIRECT(CONCATENATE("'",$C30,$E30,"'","!",$H$3,$M30))+INDIRECT(CONCATENATE("'",$C30,$E30,"'","!",$H$4,$M30)),"") | I30: =IFERROR(IF(I$7="PLAN",INDIRECT(CONCATENATE("'",$C30,$E30,"'","!",$I$2,$N30)),INDIRECT(CONCATENATE("'",$C30,$E30,"'","!",$I$2,$M30))),"") | J30: =IFERROR(IF(J$7="PLAN",INDIRECT(CONCATENATE("'",$C30,$E30,"'","!",$J$2,$N30)),INDIRECT(CONCATENATE("'",$C30,$E30,"'","!",$J$2,$M30))),"") | K30: =IFERROR(IF(K$7="PLAN",INDIRECT(CONCATENATE("'",$C30,$E30,"'","!",$K$2,$N30)),INDIRECT(CONCATENATE("'",$C30,$E30,"'","!",$K$2,$M30))),"") | M30: 93 | N30: 322
... C47: =VLOOKUP($F47,$AS:$AT,2,FALSE) -> [AT_WR_43_2022_SHOPS.xlsx] | D47: Deputy manager | E47: =E46 -> Paniglgasse | F47: =VLOOKUP($E47,$AP:$AQ,2,FALSE) -> AT | G47: =D47&E47 -> Deputy managerPaniglgasse | H47: =IFERROR(INDIRECT(CONCATENATE("'",$C47,$E47,"'","!",$H$2,$M47))+INDIRECT(CONCATENATE("'",$C47,$E47,"'","!",$H$3,$M47))+INDIRECT(CONCATENATE("'",$C47,$E47,"'","!",$H$4,$M47)),"") | I47: =IFERROR(IF(I$7="PLAN",INDIRECT(CONCATENATE("'",$C47,$E47,"'","!",$I$2,$N47)),INDIRECT(CONCATENATE("'",$C47,$E47,"'","!",$I$2,$M47))),"") | J47: =IFERROR(IF(J$7="PLAN",INDIRECT(CONCATENATE("'",$C47,$E47,"'","!",$J$2,$N47)),INDIRECT(CONCATENATE("'",$C47,$E47,"'","!",$J$2,$M47))),"") | K47: =IFERROR(IF(K$7="PLAN",INDIRECT(CONCATENATE("'",$C47,$E47,"'","!",$K$2,$N47)),INDIRECT(CONCATENATE("'",$C47,$E47,"'","!",$K$2,$M47))),"") | M47: 124 | N47: 353
C48: =VLOOKUP($F48,$AS:$AT,2,FALSE) -> [AT_WR_43_2022_SHOPS.xlsx] | D48: Assistents | E48: =E46 -> Paniglgasse | F48: =VLOOKUP($E48,$AP:$AQ,2,FALSE) -> AT | G48: =D48&E48 -> AssistentsPaniglgasse | H48: =IFERROR(INDIRECT(CONCATENATE("'",$C48,$E48,"'","!",$H$2,$M48))+INDIRECT(CONCATENATE("'",$C48,$E48,"'","!",$H$3,$M48))+INDIRECT(CONCATENATE("'",$C48,$E48,"'","!",$H$4,$M48)),"") | I48: =IFERROR(IF(I$7="PLAN",INDIRECT(CONCATENATE("'",$C48,$E48,"'","!",$I$2,$N48)),INDIRECT(CONCATENATE("'",$C48,$E48,"'","!",$I$2,$M48))),"") | J48: =IFERROR(IF(J$7="PLAN",INDIRECT(CONCATENATE("'",$C48,$E48,"'","!",$J$2,$N48)),INDIRECT(CONCATENATE("'",$C48,$E48,"'","!",$J$2,$M48))),"") | K48: =IFERROR(IF(K$7="PLAN",INDIRECT(CONCATENATE("'",$C48,$E48,"'","!",$K$2,$N48)),INDIRECT(CONCATENATE("'",$C48,$E48,"'","!",$K$2,$M48))),"") | M48: 125 | N48: 354
C49: =VLOOKUP($F49,$AS:$AT,2,FALSE) -> [AT_WR_43_2022_SHOPS.xlsx] | D49: Stock keeper | E49: =E48 -> Paniglgasse | F49: =VLOOKUP($E49,$AP:$AQ,2,FALSE) -> AT | G49: =D49&E49 -> Stock keeperPaniglgasse | H49: =IFERROR(INDIRECT(CONCATENATE("'",$C49,$E49,"'","!",$H$2,$M49))+INDIRECT(CONCATENATE("'",$C49,$E49,"'","!",$H$3,$M49))+INDIRECT(CONCATENATE("'",$C49,$E49,"'","!",$H$4,$M49)),"") | I49: =IFERROR(IF(I$7="PLAN",INDIRECT(CONCATENATE("'",$C49,$E49,"'","!",$I$2,$N49)),INDIRECT(CONCATENATE("'",$C49,$E49,"'","!",$I$2,$M49))),"") | J49: =IFERROR(IF(J$7="PLAN",INDIRECT(CONCATENATE("'",$C49,$E49,"'","!",$J$2,$N49)),INDIRECT(CONCATENATE("'",$C49,$E49,"'","!",$J$2,$M49))),"") | K49: =IFERROR(IF(K$7="PLAN",INDIRECT(CONCATENATE("'",$C49,$E49,"'","!",$K$2,$N49)),INDIRECT(CONCATENATE("'",$C49,$E49,"'","!",$K$2,$M49))),"") | M49: 126 | N49: 355
C50: =VLOOKUP($F50,$AS:$AT,2,FALSE) -> [AT_WR_43_2022_SHOPS.xlsx] | D50: Temporary employees | E50: =E49 -> Paniglgasse | F50: =VLOOKUP($E50,$AP:$AQ,2,FALSE) -> AT | G50: =D50&E50 -> Temporary employeesPaniglgasse | H50: =IFERROR(INDIRECT(CONCATENATE("'",$C50,$E50,"'","!",$H$2,$M50))+INDIRECT(CONCATENATE("'",$C50,$E50,"'","!",$H$3,$M50))+INDIRECT(CONCATENATE("'",$C50,$E50,"'","!",$H$4,$M50)),"") | I50: =IFERROR(IF(I$7="PLAN",INDIRECT(CONCATENATE("'",$C50,$E50,"'","!",$I$2,$N50)),INDIRECT(CONCATENATE("'",$C50,$E50,"'","!",$I$2,$M50))),"") | J50: =IFERROR(IF(J$7="PLAN",INDIRECT(CONCATENATE("'",$C50,$E50,"'","!",$J$2,$N50)),INDIRECT(CONCATENATE("'",$C50,$E50,"'","!",$J$2,$M50))),"") | K50: =IFERROR(IF(K$7="PLAN",INDIRECT(CONCATENATE("'",$C50,$E50,"'","!",$K$2,$N50)),INDIRECT(CONCATENATE("'",$C50,$E50,"'","!",$K$2,$M50))),"") | M50: 127 | N50: 356
C51: =VLOOKUP($F51,$AS:$AT,2,FALSE) -> [AT_WR_43_2022_SHOPS.xlsx] | D51: Shop assistants bonuses | E51: =E50 -> Paniglgasse | F51: =VLOOKUP($E51,$AP:$AQ,2,FALSE) -> AT | G51: =D51&E51 -> Shop assistants bonusesPaniglgasse | H51: =IFERROR(INDIRECT(CONCATENATE("'",$C51,$E51,"'","!",$H$2,$M51))+INDIRECT(CONCATENATE("'",$C51,$E51,"'","!",$H$3,$M51))+INDIRECT(CONCATENATE("'",$C51,$E51,"'","!",$H$4,$M51)),"") | I51: =IFERROR(IF(I$7="PLAN",INDIRECT(CONCATENATE("'",$C51,$E51,"'","!",$I$2,$N51)),INDIRECT(CONCATENATE("'",$C51,$E51,"'","!",$I$2,$M51))),"") | J51: =IFERROR(IF(J$7="PLAN",INDIRECT(CONCATENATE("'",$C51,$E51,"'","!",$J$2,$N51)),INDIRECT(CONCATENATE("'",$C51,$E51,"'","!",$J$2,$M51))),"") | K51: =IFERROR(IF(K$7="PLAN",INDIRECT(CONCATENATE("'",$C51,$E51,"'","!",$K$2,$N51)),INDIRECT(CONCATENATE("'",$C51,$E51,"'","!",$K$2,$M51))),"") | M51: 128 | N51: 357
C52: =VLOOKUP($F52,$AS:$AT,2,FALSE) -> [AT_WR_43_2022_SHOPS.xlsx] | D52: Shop manager bonuses | E52: =E51 -> Paniglgasse | F52: =VLOOKUP($E52,$AP:$AQ,2,FALSE) -> AT | G52: =D52&E52 -> Shop manager bonusesPaniglgasse | H52: =IFERROR(INDIRECT(CONCATENATE("'",$C52,$E52,"'","!",$H$2,$M52))+INDIRECT(CONCATENATE("'",$C52,$E52,"'","!",$H$3,$M52))+INDIRECT(CONCATENATE("'",$C52,$E52,"'","!",$H$4,$M52)),"") | I52: =IFERROR(IF(I$7="PLAN",INDIRECT(CONCATENATE("'",$C52,$E52,"'","!",$I$2,$N52)),INDIRECT(CONCATENATE("'",$C52,$E52,"'","!",$I$2,$M52))),"") | J52: =IFERROR(IF(J$7="PLAN",INDIRECT(CONCATENATE("'",$C52,$E52,"'","!",$J$2,$N52)),INDIRECT(CONCATENATE("'",$C52,$E52,"'","!",$J$2,$M52))),"") | K52: =IFERROR(IF(K$7="PLAN",INDIRECT(CONCATENATE("'",$C52,$E52,"'","!",$K$2,$N52)),INDIRECT(CONCATENATE("'",$C52,$E52,"'","!",$K$2,$M52))),"") | M52: 129 | N52: 358
C53: =VLOOKUP($F53,$AS:$AT,2,FALSE) -> [AT_WR_43_2022_SHOPS.xlsx] | D53: Social tax | E53: =E52 -> Paniglgasse | F53: =VLOOKUP($E53,$AP:$AQ,2,FALSE) -> AT | G53: =D53&E53 -> Social taxPaniglgasse | H53: =IFERROR(INDIRECT(CONCATENATE("'",$C53,$E53,"'","!",$H$2,$M53))+INDIRECT(CONCATENATE("'",$C53,$E53,"'","!",$H$3,$M53))+INDIRECT(CONCATENATE("'",$C53,$E53,"'","!",$H$4,$M53)),"") | I53: =IFERROR(IF(I$7="PLAN",INDIRECT(CONCATENATE("'",$C53,$E53,"'","!",$I$2,$N53)),INDIRECT(CONCATENATE("'",$C53,$E53,"'","!",$I$2,$M53))),"") | J53: =IFERROR(IF(J$7="PLAN",INDIRECT(CONCATENATE("'",$C53,$E53,"'","!",$J$2,$N53)),INDIRECT(CONCATENATE("'",$C53,$E53,"'","!",$J$2,$M53))),"") | K53: =IFERROR(IF(K$7="PLAN",INDIRECT(CONCATENATE("'",$C53,$E53,"'","!",$K$2,$N53)),INDIRECT(CONCATENATE("'",$C53,$E53,"'","!",$K$2,$M53))),"") | M53: 130 | N53: 359
C54: =VLOOKUP($F54,$AS:$AT,2,FALSE) -> [AT_WR_43_2022_SHOPS.xlsx] | D54: Benefits | E54: =E53 -> Paniglgasse | F54: =VLOOKUP($E54,$AP:$AQ,2,FALSE) -> AT | G54: =D54&E54 -> BenefitsPaniglgasse | H54: =IFERROR(INDIRECT(CONCATENATE("'",$C54,$E54,"'","!",$H$2,$M54))+INDIRECT(CONCATENATE("'",$C54,$E54,"'","!",$H$3,$M54))+INDIRECT(CONCATENATE("'",$C54,$E54,"'","!",$H$4,$M54)),"") | I54: =IFERROR(IF(I$7="PLAN",INDIRECT(CONCATENATE("'",$C54,$E54,"'","!",$I$2,$N54)),INDIRECT(CONCATENATE("'",$C54,$E54,"'","!",$I$2,$M54))),"") | J54: =IFERROR(IF(J$7="PLAN",INDIRECT(CONCATENATE("'",$C54,$E54,"'","!",$J$2,$N54)),INDIRECT(CONCATENATE("'",$C54,$E54,"'","!",$J$2,$M54))),"") | K54: =IFERROR(IF(K$7="PLAN",INDIRECT(CONCATENATE("'",$C54,$E54,"'","!",$K$2,$N54)),INDIRECT(CONCATENATE("'",$C54,$E54,"'","!",$K$2,$M54))),"") | M54: 131 | N54: 360
C55: =VLOOKUP($F55,$AS:$AT,2,FALSE) -> [AT_WR_43_2022_SHOPS.xlsx] | D55: Leasing of staff | E55: =E54 -> Paniglgasse | F55: =VLOOKUP($E55,$AP:$AQ,2,FALSE) -> AT | G55: =D55&E55 -> Leasing of staffPaniglgasse | H55: =IFERROR(INDIRECT(CONCATENATE("'",$C55,$E55,"'","!",$H$2,$M55))+INDIRECT(CONCATENATE("'",$C55,$E55,"'","!",$H$3,$M55))+INDIRECT(CONCATENATE("'",$C55,$E55,"'","!",$H$4,$M55)),"") | I55: =IFERROR(IF(I$7="PLAN",INDIRECT(CONCATENATE("'",$C55,$E55,"'","!",$I$2,$N55)),INDIRECT(CONCATENATE("'",$C55,$E55,"'","!",$I$2,$M55))),"") | J55: =IFERROR(IF(J$7="PLAN",INDIRECT(CONCATENATE("'",$C55,$E55,"'","!",$J$2,$N55)),INDIRECT(CONCATENATE("'",$C55,$E55,"'","!",$J$2,$M55))),"") | K55: =IFERROR(IF(K$7="PLAN",INDIRECT(CONCATENATE("'",$C55,$E55,"'","!",$K$2,$N55)),INDIRECT(CONCATENATE("'",$C55,$E55,"'","!",$K$2,$M55))),"") | M55: 132 | N55: 361 | Q55: =VLOOKUP($F55,$AS:$AT,2,FALSE) -> [AT_WR_43_2022_SHOPS.xlsx] | R55: Operating Result | S55: =+E55 -> Paniglgasse | T55: =VLOOKUP($E55,$AP:$AQ,2,FALSE) -> AT | U55: =R55&S55 -> Operating ResultPaniglgasse | V55: =IFERROR(INDIRECT(CONCATENATE("'",$Q55,$S55,"'","!",$V$2,$AA55))+INDIRECT(CONCATENATE("'",$Q55,$S55,"'","!",$V$3,$AA55))+INDIRECT(CONCATENATE("'",$C55,$E55,"'","!",$V$4,$AA55)),"") | W55: =IFERROR(IF(W$7="PLAN",INDIRECT(CONCATENATE("'",$Q55,$S55,"'","!",$W$2,$AB55)),INDIRECT(CONCATENATE("'",$Q55,$S55,"'","!",$I$2,$AA55))),"") | X55: =IFERROR(IF(X$7="PLAN",INDIRECT(CONCATENATE("'",$Q55,$S55,"'","!",$X$2,$AB55)),INDIRECT(CONCATENATE("'",$Q55,$S55,"'","!",$X$2,$AA55))),"") | Y55: =IFERROR(IF(Y$7="PLAN",INDIRECT(CONCATENATE("'",$Q55,$S55,"'","!",$Y$2,$AB55)),INDIRECT(CONCATENATE("'",$C55,$E55,"'","!",$K$2,$AA55))),"") | AA55: 136 | AB55: 365 | AD55: -71196.983 | AE55: -4301.6827 | AF55: -4039.6513 | AG55: 8581.9543 | AI55: =+H20-SUM(H21:H55)-AD55 -> #VALUE! | AJ55: =+I20-SUM(I21:I55)-AE55 -> #VALUE! | AK55: =+J20-SUM(J21:J55)-AF55 -> #VALUE! | AL55: =+K20-SUM(K21:K55)-AG55 -> #VALUE!
C56: =VLOOKUP($F56,$AS:$AT,2,FALSE) -> [AT_WR_43_2022_SHOPS.xlsx] | D56: Kgs put into the shop-Shop_A | E56: =AP10 -> Lerchenfelder | F56: =VLOOKUP($E56,$AP:$AQ,2,FALSE) -> AT | G56: =D56&E56 -> Kgs put into the shop-Shop_ALerchenfelder | H56: =IFERROR(INDIRECT(CONCATENATE("'",$C56,$E56,"'","!",$H$2,$M56))+INDIRECT(CONCATENATE("'",$C56,$E56,"'","!",$H$3,$M56))+INDIRECT(CONCATENATE("'",$C56,$E56,"'","!",$H$4,$M56)),"") | I56: =IFERROR(IF(I$7="PLAN",INDIRECT(CONCATENATE("'",$C56,$E56,"'","!",$I$2,$N56)),INDIRECT(CONCATENATE("'",$C56,$E56,"'","!",$I$2,$M56))),"") | J56: =IFERROR(IF(J$7="PLAN",INDIRECT(CONCATENATE("'",$C56,$E56,"'","!",$J$2,$N56)),INDIRECT(CONCATENATE("'",$C56,$E56,"'","!",$J$2,$M56))),"") | K56: =IFERROR(IF(K$7="PLAN",INDIRECT(CONCATENATE("'",$C56,$E56,"'","!",$K$2,$N56)),INDIRECT(CONCATENATE("'",$C56,$E56,"'","!",$K$2,$M56))),"") | M56: 37 | N56: 283
C57: =VLOOKUP($F57,$AS:$AT,2,FALSE) -> [AT_WR_43_2022_SHOPS.xlsx] | D57: Kgs put into the shop-Shop_B | E57: =E56 -> Lerchenfelder | F57: =VLOOKUP($E57,$AP:$AQ,2,FALSE) -> AT | G57: =D57&E57 -> Kgs put into the shop-Shop_BLerchenfelder | H57: =IFERROR(INDIRECT(CONCATENATE("'",$C57,$E57,"'","!",$H$2,$M57))+INDIRECT(CONCATENATE("'",$C57,$E57,"'","!",$H$3,$M57))+INDIRECT(CONCATENATE("'",$C57,$E57,"'","!",$H$4,$M57)),"") | I57: =IFERROR(IF(I$7="PLAN",INDIRECT(CONCATENATE("'",$C57,$E57,"'","!",$I$2,$N57)),INDIRECT(CONCATENATE("'",$C57,$E57,"'","!",$I$2,$M57))),"") | J57: =IFERROR(IF(J$7="PLAN",INDIRECT(CONCATENATE("'",$C57,$E57,"'","!",$J$2,$N57)),INDIRECT(CONCATENATE("'",$C57,$E57,"'","!",$J$2,$M57))),"") | K57: =IFERROR(IF(K$7="PLAN",INDIRECT(CONCATENATE("'",$C57,$E57,"'","!",$K$2,$N57)),INDIRECT(CONCATENATE("'",$C57,$E57,"'","!",$K$2,$M57))),"") | M57: 38 | N57: 284
C58: =VLOOKUP($F58,$AS:$AT,2,FALSE) -> [AT_WR_43_2022_SHOPS.xlsx] | D58: Kgs put into the shop-Shoes_A | E58: =E57 -> Lerchenfelder | F58: =VLOOKUP($E58,$AP:$AQ,2,FALSE) -> AT | G58: =D58&E58 -> Kgs put into the shop-Shoes_ALerchenfelder | H58: =IFERROR(INDIRECT(CONCATENATE("'",$C58,$E58,"'","!",$H$2,$M58))+INDIRECT(CONCATENATE("'",$C58,$E58,"'","!",$H$3,$M58))+INDIRECT(CONCATENATE("'",$C58,$E58,"'","!",$H$4,$M58)),"") | I58: =IFERROR(IF(I$7="PLAN",INDIRECT(CONCATENATE("'",$C58,$E58,"'","!",$I$2,$N58)),INDIRECT(CONCATENATE("'",$C58,$E58,"'","!",$I$2,$M58))),"") | J58: =IFERROR(IF(J$7="PLAN",INDIRECT(CONCATENATE("'",$C58,$E58,"'","!",$J$2,$N58)),INDIRECT(CONCATENATE("'",$C58,$E58,"'","!",$J$2,$M58))),"") | K58: =IFERROR(IF(K$7="PLAN",INDIRECT(CONCATENATE("'",$C58,$E58,"'","!",$K$2,$N58)),INDIRECT(CONCATENATE("'",$C58,$E58,"'","!",$K$2,$M58))),"") | M58: 40 | N58: 285
C59: =VLOOKUP($F59,$AS:$AT,2,FALSE) -> [AT_WR_43_2022_SHOPS.xlsx] | D59: Kgs put into the shop-Shoes_B | E59: =E58 -> Lerchenfelder | F59: =VLOOKUP($E59,$AP:$AQ,2,FALSE) -> AT | G59: =D59&E59 -> Kgs put into the shop-Shoes_BLerchenfelder | H59: =IFERROR(INDIRECT(CONCATENATE("'",$C59,$E59,"'","!",$H$2,$M59))+INDIRECT(CONCATENATE("'",$C59,$E59,"'","!",$H$3,$M59))+INDIRECT(CONCATENATE("'",$C59,$E59,"'","!",$H$4,$M59)),"") | I59: =IFERROR(IF(I$7="PLAN",INDIRECT(CONCATENATE("'",$C59,$E59,"'","!",$I$2,$N59)),INDIRECT(CONCATENATE("'",$C59,$E59,"'","!",$I$2,$M59))),"") | J59: =IFERROR(IF(J$7="PLAN",INDIRECT(CONCATENATE("'",$C59,$E59,"'","!",$J$2,$N59)),INDIRECT(CONCATENATE("'",$C59,$E59,"'","!",$J$2,$M59))),"") | K59: =IFERROR(IF(K$7="PLAN",INDIRECT(CONCATENATE("'",$C59,$E59,"'","!",$K$2,$N59)),INDIRECT(CONCATENATE("'",$C59,$E59,"'","!",$K$2,$M59))),"") | M59: 41 | N59: 286
...

Sheet Info
B1: Business unit name: | D1: Textile House Austria | AE1: valid from 1.1.2025 | AI1: valid from 1.1.2025
A2: No. | B2: SHOP | C2: Cycle | D2: Size | E2: City | F2: Region | G2: Opened (date) | H2: Closed (date) | I2: Area manager | J2: CC | K2: Comparable shop | N2: Year | O2: Current quarter | P2: Exchange rate | Q2: Budget VAT rate | R2: Actual VAT rate | S2: Budget Social tax | U2: Prices for shops | V2: Prices for shops EUR | X2: Previous Year | Y2: Exchange rate | AE2: Regular shops | AF2: Prices for shops | AG2: Prices for shops EUR | AI2: Vintage shops | AJ2: Prices for shops | AK2: Prices for shops EUR
A3: 1 | B3: Paniglgasse | C3: vintage | E3: Vienna | F3: Area 1 | G3: 44613 | I3: Petra Fratričová | L3: =K3&C3 -> vintage | N3: 2025 | O3: Q1 | P3: 1 | Q3: 0.2 | R3: 0.2 | S3: 0.2276 | T3: A | U3: =V3*$P$3 -> 4.8 | V3: 4.8 | X3: 2024 | Y3: 1 | Z3: Kgs put into the shop, shop A | AE3: A | AF3: =AG3*$P$3 -> 4.8 | AG3: 4.8 | AI3: Trend A | AJ3: =AK3*$P$3 -> 5.2 | AK3: 5.2
A4: 2 | B4: Lerchenfelder | C4: vintage | E4: Vienna | F4: Area 1 | I4: Petra Fratričová | L4: =K4&C4 -> vintage | T4: B | U4: =V4*$P$3 -> 2 | V4: 2 | Z4: Kgs put into the shop, shop B | AE4: Shoes A | AF4: =AG4*$P$3 -> 4.8 | AG4: 4.8 | AI4: Trend Shoes A | AJ4: =AK4*$P$3 -> 5.2 | AK4: 5.2
A5: 3 | B5: Landstrasser_Hauptstrasse | C5: vintage | E5: Vienna | F5: Area 1 | I5: Petra Fratričová | L5: =K5&C5 -> vintage | T5: Shoes A | U5: =V5*$P$3 -> 4.8 | V5: 4.8 | Z5: Kgs put into the shop, HHR | AE5: B | AF5: =AG5*$P$3 -> 2 | AG5: 2 | AI5: Trend B | AJ5: =AK5*$P$3 -> 2.4 | AK5: 2.4
A6: 4 | B6: New shop 2 | L6: =K6&C6 | T6: Shoes B | U6: =V6*$P$3 -> 2 | V6: 2 | Z6: Kgs put into the shop, shoes A | AE6: Shoes B | AF6: =AG6*$P$3 -> 2.4 | AG6: 2.4 | AI6: Shoes B | AJ6: =AK6*$P$3 -> 2.4 | AK6: 2.4
A7: 5 | L7: =K7&C7 | T7: HHR (standard) | U7: =V7*$P$3 -> 2 | V7: 2 | Z7: Kgs put into the shop, shoes B | AE7: HHR (standard) | AF7: =AG7*$P$3 -> 2 | AG7: 2 | AI7: Trend HHR | AJ7: =AK7*$P$3 -> 2.4 | AK7: 2.4
A8: 6 | L8: =K8&C8 | T8: Mix Summer | U8: =V8*$P$3 -> 0.8 | V8: 0.8 | Z8: Kgs put into the shop, Mix Summer | AE8: HHT (heavy) | AF8: =AG8*$P$3 -> 2 | AG8: 2 | AI8: HHT (heavy) | AJ8: =AK8*$P$3 -> 0
A9: 7 | T9: Mix Winter | U9: =V9*$P$3 -> 0.7 | V9: 0.7 | Z9: Kgs put into the shop, Mix Winter | AE9: Mix Summer | AF9: =AG9*$P$3 -> 0.8 | AG9: 0.8 | AI9: Mix Summer | AJ9: =AK9*$P$3 -> 0.8 | AK9: 0.8
A10: 8 | T10: Handbag A | U10: =V10*$P$3 -> 4.8 | V10: 4.8 | Z10: Kgs put into the shop, Handbag A | AE10: Mix Winter | AF10: =AG10*$P$3 -> 0.7 | AG10: 0.7 | AI10: Mix Winter | AJ10: =AK10*$P$3 -> 0.7 | AK10: 0.7
A11: 9 | L11: =K10&C10 | T11: Handbag B | U11: =V11*$P$3 -> 2 | V11: 2 | Z11: Kgs put into the shop, Handbag B | AE11: Handbag A | AF11: =AG11*$P$3 -> 4.8 | AG11: 4.8 | AI11: Bag A Trendy | AJ11: =AK11*$P$3 -> 5.2 | AK11: 5.2
A12: 10 | L12: =K11&C11 | T12: Things | U12: =V12*$P$3 -> 4.8 | V12: 4.8 | Z12: Kgs put into the shop, things | AE12: Handbag B | AF12: =AG12*$P$3 -> 2.4 | AG12: 2.4 | AI12: Handbag B | AJ12: =AK12*$P$3 -> 2.4 | AK12: 2.4
A13: 11 | L13: =K12&C12 | AE13: return | AF13: =AG13*$P$3 -> 0.2 | AG13: 0.2 | AI13: Other Trend categories | AJ13: =AK13*$P$3 -> 5.2 | AK13: 5.2
A14: 12 | L14: =K13&C13 | AE14: hhr b | AF14: =AG14*$P$3 -> 1.3 | AG14: 1.3 | AI14: hhr b | AJ14: =AK14*$P$3 -> 1.3 | AK14: 1.3
A15: 13 | L15: =K14&C14
A16: 14 | L16: =K15&C15
A17: 15 | L17: =K16&C16
A18: 16 | L18: =K17&C17
A19: 17 | D19: ` | L19: =K18&C18
A20: 18 | L20: =K19&C19
A21: 19 | L21: =K20&C20
A22: 20 | L22: =K21&C21
A23: 21 | L23: =K22&C22
A24: 22 | L24: =K23&C23
A25: 23 | L25: =K24&C24
A26: 24 | L26: =K25&C25
A27: 25 | L27: =K26&C26
A28: 26 | L28: =K27&C27
A29: 27 | L29: =K28&C28
A30: 28 | L30: =K29&C29
A31: 29 | L31: =K30&C30
... A50: 48 | L50: =K49&C49
B51: Total | D51: =SUM(D3:D50) -> 0 | L51: =K50&C50
B52: 5 weeks | D52: =SUMIF($C$3:$C$50,$B52,$D$3:$D$50) -> 0
B53: 2 weeks | D53: =SUMIF($C$3:$C$50,$B53,$D$3:$D$50) -> 0

Sheet WK5
D1: =Info!$N$3 -> 2025 | E1: 1st Quarter | R1: 2nd Quarter | AE1: 3rd Quarter | AR1: 4th Quarter | BF1: Q1 | BI1: Q2 | BL1: Q3 | BO1: Q4
B2: =Info!$D$1 -> Textile House Austria | E2: January | I2: February | M2: March | R2: April | V2: May | Z2: June | AE2: July | AI2: August | AM2: September | AR2: October | AV2: November | AZ2: December | BF2: January | BG2: February | BH2: March | BI2: April | BJ2: May | BK2: June | BL2: July | BM2: August | BN2: September | BO2: October | BP2: November | BQ2: December | BR2: Year | BS2: Q1 | BT2: Q2 | BU2: Q3 | BV2: Q4 | BW2: H1 | BX2: H2 | BY2: Selection | BZ2: Selection
B3: 5 week | E3: Week | F3: Week | G3: Week | H3: Week | I3: Week | J3: Week | K3: Week | L3: Week | M3: Week | N3: Week | O3: Week | P3: Week | Q3: Week | R3: Week | S3: Week | T3: Week | U3: Week | V3: Week | W3: Week | X3: Week | Y3: Week | Z3: Week | AA3: Week | AB3: Week | AC3: Week | AD3: Week | AE3: Week | AF3: Week | AG3: Week | AH3: Week | AI3: Week | AJ3: Week | AK3: Week | AL3: Week | AM3: Week | AN3: Week | AO3: Week | AP3: Week | AQ3: Week | AR3: Week | AS3: Week | AT3: Week | AU3: Week | AV3: Week | AW3: Week | AX3: Week | AY3: Week | AZ3: Week | BA3: Week | BB3: Week | BC3: Week | BD3: Week | BF3: 1-4 | BG3: 5-8 | BH3: 9-13 | BI3: 14-17 | BJ3: 18-21 | BK3: 22-26 | BL3: 27-30 | BM3: 31-34 | BN3: 35-39 | BO3: 40-43 | BP3: 44-47 | BQ3: 48-52 | BR3: =$D$1 -> 2025 | BS3: 1-13 | BT3: 14-26 | BU3: 27-39 | BV3: 40-52 | BW3: 1-26 | BX3: 27-52 | BY3: YTD | BZ3: Quarter
D4: Total | E4: 1 | F4: 2 | G4: 3 | H4: 4 | I4: 5 | J4: 6 | K4: 7 | L4: 8 | M4: 9 | N4: 10 | O4: 11 | P4: 12 | Q4: 13 | R4: 14 | S4: 15 | T4: 16 | U4: 17 | V4: 18 | W4: 19 | X4: 20 | Y4: 21 | Z4: 22 | AA4: 23 | AB4: 24 | AC4: 25 | AD4: 26 | AE4: 27 | AF4: 28 | AG4: 29 | AH4: 30 | AI4: 31 | AJ4: 32 | AK4: 33 | AL4: 34 | AM4: 35 | AN4: 36 | AO4: 37 | AP4: 38 | AQ4: 39 | AR4: 40 | AS4: 41 | AT4: 42 | AU4: 43 | AV4: 44 | AW4: 45 | AX4: 46 | AY4: 47 | AZ4: 48 | BA4: 49 | BB4: 50 | BC4: 51 | BD4: 52 | BF4: 4 | BG4: 4 | BH4: 5 | BI4: 4 | BJ4: 4 | BK4: 5 | BL4: 4 | BM4: 4 | BN4: 5 | BO4: 4 | BP4: 4 | BQ4: 5
B5: Pieces stolen | D5: =SUM(E5:BD5) -> 1158 | E5: =SUM(Paniglgasse:Lerchenfelder!E5) -> 86.03 | F5: =SUM(Paniglgasse:Lerchenfelder!F5) -> -25.18 | G5: =SUM(Paniglgasse:Lerchenfelder!G5) -> -76.63 | H5: =SUM(Paniglgasse:Lerchenfelder!H5) -> 10.68 | I5: =SUM(Paniglgasse:Lerchenfelder!I5) -> -39 | J5: =SUM(Paniglgasse:Lerchenfelder!J5) -> 41.56 | K5: =SUM(Paniglgasse:Lerchenfelder!K5) -> 10 | L5: =SUM(Paniglgasse:Lerchenfelder!L5) -> 39.15 | ... BD5: =SUM(Paniglgasse:Lerchenfelder!BD5) -> 0 | BF5: =SUM(E5:H5) -> -5.1 | BG5: =SUM(I5:L5) -> 51.71 | BH5: =SUM(M5:Q5) -> 127.12 | BI5: =SUM(R5:U5) -> 389.35 | BJ5: =SUM(V5:Y5) -> 264.66 | BK5: =SUM(Z5:AD5) -> 73.39 | BL5: =SUM(AE5:AH5) -> 109.81 | BM5: =SUM(AI5:AL5) -> 114.72 | BN5: =SUM(AM5:AQ5) -> 32.34 | BO5: =SUM(AR5:AU5) -> 0 | BP5: =SUM(AV5:AY5) -> 0 | BQ5: =SUM(AZ5:BD5) -> 0 | BR5: =SUM(BF5:BQ5) -> 1158 | BS5: =SUM(BF5:BH5) -> 173.73 | BT5: =SUM(BI5:BK5) -> 727.4 | BU5: =SUM(BL5:BN5) -> 256.87 | BV5: =SUM(BO5:BQ5) -> 0 | BW5: =SUM(BF5:BK5) -> 901.13 | BX5: =SUM(BL5:BQ5) -> 256.87 | BY5: =IF(Info!$O$3="Q1",$BS5,IF(Info!$O$3="Q2",$BS5+$BT5,IF(Info!$O$3="Q3",$BS5+$BT5+$BU5,$BR5))) -> 173.73 | BZ5: =IF(Info!$O$3="Q1",$BS5,IF(Info!$O$3="Q2",$BT5,IF(Info!$O$3="Q3",$BU5,$BV5))) -> 173.73
B6: Pcs in the shop, week begin | D6: =SUM(E6:BD6) -> 135546.92 | E6: =SUM(Paniglgasse:Lerchenfelder!E6) -> 2869.15 | F6: =IF(F15=0,E32,F15) -> 2477.79 | G6: =IF(G15=0,F32,G15) -> 2360.66 | H6: =IF(H15=0,G32,H15) -> 3674.4 | I6: =IF(I15=0,H32,I15) -> 2754.08 | J6: =IF(J15=0,I32,J15) -> 2746.6 | K6: =IF(K15=0,J32,K15) -> 2811.36 | L6: =IF(L15=0,K32,L15) -> 2588.68 | M6: =IF(M15=0,L32,M15) -> 3948.89 | ... BD6: =IF(BD15=0,BC32,BD15) -> 1703.2 | BF6: =SUM(E6:H6) -> 11382 | BG6: =SUM(I6:L6) -> 10900.72 | BH6: =SUM(M6:Q6) -> 16145.63 | BI6: =SUM(R6:U6) -> 13659.79 | BJ6: =SUM(V6:Y6) -> 12952.87 | BK6: =SUM(Z6:AD6) -> 15625.07 | BL6: =SUM(AE6:AH6) -> 11613.97 | BM6: =SUM(AI6:AL6) -> 10694.05 | BN6: =SUM(AM6:AQ6) -> 10431.22 | BO6: =SUM(AR6:AU6) -> 6812.8 | BP6: =SUM(AV6:AY6) -> 6812.8 | BQ6: =SUM(AZ6:BD6) -> 8516 | BR6: =SUM(BF6:BQ6) -> 135546.92 | BS6: =SUM(BF6:BH6) -> 38428.35 | BT6: =SUM(BI6:BK6) -> 42237.73 | BU6: =SUM(BL6:BN6) -> 32739.24 | BV6: =SUM(BO6:BQ6) -> 22141.6 | BW6: =SUM(BF6:BK6) -> 80666.08 | BX6: =SUM(BL6:BQ6) -> 54880.84 | BY6: =IF(Info!$O$3="Q1",$BS6,IF(Info!$O$3="Q2",$BS6+$BT6,IF(Info!$O$3="Q3",$BS6+$BT6+$BU6,$BR6))) -> 38428.35 | BZ6: =IF(Info!$O$3="Q1",$BS6,IF(Info!$O$3="Q2",$BT6,IF(Info!$O$3="Q3",$BU6,$BV6))) -> 38428.35
B7: Pcs put into the shop, A new opening | D7: =SUM(E7:BD7) -> 24095.11 | E7: =SUM(Paniglgasse:Lerchenfelder!E7) -> 0 | F7: =SUM(Paniglgasse:Lerchenfelder!F7) -> 0 | G7: =SUM(Paniglgasse:Lerchenfelder!G7) -> 0 | H7: =SUM(Paniglgasse:Lerchenfelder!H7) -> 3296.87 | I7: =SUM(Paniglgasse:Lerchenfelder!I7) -> 0 | J7: =SUM(Paniglgasse:Lerchenfelder!J7) -> 0 | K7: =SUM(Paniglgasse:Lerchenfelder!K7) -> 0 | L7: =SUM(Paniglgasse:Lerchenfelder!L7) -> 0 | ... BD7: =SUM(Paniglgasse:Lerchenfelder!BD7) -> 0 | BF7: =SUM(E7:H7) -> 3296.87 | BG7: =SUM(I7:L7) -> 0 | BH7: =SUM(M7:Q7) -> 3535.24 | BI7: =SUM(R7:U7) -> 3622.1 | BJ7: =SUM(V7:Y7) -> 3503.92 | BK7: =SUM(Z7:AD7) -> 3727.28 | BL7: =SUM(AE7:AH7) -> 3236.33 | BM7: =SUM(AI7:AL7) -> 0 | BN7: =SUM(AM7:AQ7) -> 3173.37 | BO7: =SUM(AR7:AU7) -> 0 | BP7: =SUM(AV7:AY7) -> 0 | BQ7: =SUM(AZ7:BD7) -> 0 | BR7: =SUM(BF7:BQ7) -> 24095.11 | BS7: =SUM(BF7:BH7) -> 6832.11 | BT7: =SUM(BI7:BK7) -> 10853.3 | BU7: =SUM(BL7:BN7) -> 6409.7 | BV7: =SUM(BO7:BQ7) -> 0 | BW7: =SUM(BF7:BK7) -> 17685.41 | BX7: =SUM(BL7:BQ7) -> 6409.7 | BY7: =IF(Info!$O$3="Q1",$BS7,IF(Info!$O$3="Q2",$BS7+$BT7,IF(Info!$O$3="Q3",$BS7+$BT7+$BU7,$BR7))) -> 6832.11 | BZ7: =IF(Info!$O$3="Q1",$BS7,IF(Info!$O$3="Q2",$BT7,IF(Info!$O$3="Q3",$BU7,$BV7))) -> 6832.11
B8: Pcs put into the shop, B new opening | D8: =SUM(E8:BD8) -> 0 | E8: =SUM(Paniglgasse:Lerchenfelder!E8) -> 0 | F8: =SUM(Paniglgasse:Lerchenfelder!F8) -> 0 | G8: =SUM(Paniglgasse:Lerchenfelder!G8) -> 0 | H8: =SUM(Paniglgasse:Lerchenfelder!H8) -> 0 | I8: =SUM(Paniglgasse:Lerchenfelder!I8) -> 0 | J8: =SUM(Paniglgasse:Lerchenfelder!J8) -> 0 | K8: =SUM(Paniglgasse:Lerchenfelder!K8) -> 0 | L8: =SUM(Paniglgasse:Lerchenfelder!L8) -> 0 | ... BD8: =SUM(Paniglgasse:Lerchenfelder!BD8) -> 0 | BF8: =SUM(E8:H8) -> 0 | BG8: =SUM(I8:L8) -> 0 | BH8: =SUM(M8:Q8) -> 0 | BI8: =SUM(R8:U8) -> 0 | BJ8: =SUM(V8:Y8) -> 0 | BK8: =SUM(Z8:AD8) -> 0 | BL8: =SUM(AE8:AH8) -> 0 | BM8: =SUM(AI8:AL8) -> 0 | BN8: =SUM(AM8:AQ8) -> 0 | BO8: =SUM(AR8:AU8) -> 0 | BP8: =SUM(AV8:AY8) -> 0 | BQ8: =SUM(AZ8:BD8) -> 0 | BR8: =SUM(BF8:BQ8) -> 0 | BS8: =SUM(BF8:BH8) -> 0 | BT8: =SUM(BI8:BK8) -> 0 | BU8: =SUM(BL8:BN8) -> 0 | BV8: =SUM(BO8:BQ8) -> 0 | BW8: =SUM(BF8:BK8) -> 0 | BX8: =SUM(BL8:BQ8) -> 0 | BY8: =IF(Info!$O$3="Q1",$BS8,IF(Info!$O$3="Q2",$BS8+$BT8,IF(Info!$O$3="Q3",$BS8+$BT8+$BU8,$BR8))) -> 0 | BZ8: =IF(Info!$O$3="Q1",$BS8,IF(Info!$O$3="Q2",$BT8,IF(Info!$O$3="Q3",$BU8,$BV8))) -> 0
B9: Pcs put into the shop, shoes A new opening | D9: =SUM(E9:BD9) -> 615.8 | E9: =SUM(Paniglgasse:Lerchenfelder!E9) -> 0 | F9: =SUM(Paniglgasse:Lerchenfelder!F9) -> 0 | G9: =SUM(Paniglgasse:Lerchenfelder!G9) -> 0 | H9: =SUM(Paniglgasse:Lerchenfelder!H9) -> 48.28 | I9: =SUM(Paniglgasse:Lerchenfelder!I9) -> 0 | J9: =SUM(Paniglgasse:Lerchenfelder!J9) -> 0 | K9: =SUM(Paniglgasse:Lerchenfelder!K9) -> 0 | L9: =SUM(Paniglgasse:Lerchenfelder!L9) -> 0 | ... BD9: =SUM(Paniglgasse:Lerchenfelder!BD9) -> 0 | BF9: =SUM(E9:H9) -> 48.28 | BG9: =SUM(I9:L9) -> 0 | BH9: =SUM(M9:Q9) -> 99.16 | BI9: =SUM(R9:U9) -> 55.74 | BJ9: =SUM(V9:Y9) -> 82.9 | BK9: =SUM(Z9:AD9) -> 83.01 | BL9: =SUM(AE9:AH9) -> 126.32 | BM9: =SUM(AI9:AL9) -> 0 | BN9: =SUM(AM9:AQ9) -> 120.39 | BO9: =SUM(AR9:AU9) -> 0 | BP9: =SUM(AV9:AY9) -> 0 | BQ9: =SUM(AZ9:BD9) -> 0 | BR9: =SUM(BF9:BQ9) -> 615.8 | BS9: =SUM(BF9:BH9) -> 147.44 | BT9: =SUM(BI9:BK9) -> 221.65 | BU9: =SUM(BL9:BN9) -> 246.71 | BV9: =SUM(BO9:BQ9) -> 0 | BW9: =SUM(BF9:BK9) -> 369.09 | BX9: =SUM(BL9:BQ9) -> 246.71 | BY9: =IF(Info!$O$3="Q1",$BS9,IF(Info!$O$3="Q2",$BS9+$BT9,IF(Info!$O$3="Q3",$BS9+$BT9+$BU9,$BR9))) -> 147.44 | BZ9: =IF(Info!$O$3="Q1",$BS9,IF(Info!$O$3="Q2",$BT9,IF(Info!$O$3="Q3",$BU9,$BV9))) -> 147.44
B10: Pcs put into the shop, shoes B new opening | D10: =SUM(E10:BD10) -> 0 | E10: =SUM(Paniglgasse:Lerchenfelder!E10) -> 0 | F10: =SUM(Paniglgasse:Lerchenfelder!F10) -> 0 | G10: =SUM(Paniglgasse:Lerchenfelder!G10) -> 0 | H10: =SUM(Paniglgasse:Lerchenfelder!H10) -> 0 | I10: =SUM(Paniglgasse:Lerchenfelder!I10) -> 0 | J10: =SUM(Paniglgasse:Lerchenfelder!J10) -> 0 | K10: =SUM(Paniglgasse:Lerchenfelder!K10) -> 0 | L10: =SUM(Paniglgasse:Lerchenfelder!L10) -> 0 | ... BD10: =SUM(Paniglgasse:Lerchenfelder!BD10) -> 0 | BF10: =SUM(E10:H10) -> 0 | BG10: =SUM(I10:L10) -> 0 | BH10: =SUM(M10:Q10) -> 0 | BI10: =SUM(R10:U10) -> 0 | BJ10: =SUM(V10:Y10) -> 0 | BK10: =SUM(Z10:AD10) -> 0 | BL10: =SUM(AE10:AH10) -> 0 | BM10: =SUM(AI10:AL10) -> 0 | BN10: =SUM(AM10:AQ10) -> 0 | BO10: =SUM(AR10:AU10) -> 0 | BP10: =SUM(AV10:AY10) -> 0 | BQ10: =SUM(AZ10:BD10) -> 0 | BR10: =SUM(BF10:BQ10) -> 0 | BS10: =SUM(BF10:BH10) -> 0 | BT10: =SUM(BI10:BK10) -> 0 | BU10: =SUM(BL10:BN10) -> 0 | BV10: =SUM(BO10:BQ10) -> 0 | BW10: =SUM(BF10:BK10) -> 0 | BX10: =SUM(BL10:BQ10) -> 0 | BY10: =IF(Info!$O$3="Q1",$BS10,IF(Info!$O$3="Q2",$BS10+$BT10,IF(Info!$O$3="Q3",$BS10+$BT10+$BU10,$BR10))) -> 0 | BZ10: =IF(Info!$O$3="Q1",$BS10,IF(Info!$O$3="Q2",$BT10,IF(Info!$O$3="Q3",$BU10,$BV10))) -> 0
B11: Pcs put into the shop, HHR new opening | D11: =SUM(E11:BD11) -> 0 | E11: =SUM(Paniglgasse:Lerchenfelder!E11) -> 0 | F11: =SUM(Paniglgasse:Lerchenfelder!F11) -> 0 | G11: =SUM(Paniglgasse:Lerchenfelder!G11) -> 0 | H11: =SUM(Paniglgasse:Lerchenfelder!H11) -> 0 | I11: =SUM(Paniglgasse:Lerchenfelder!I11) -> 0 | J11: =SUM(Paniglgasse:Lerchenfelder!J11) -> 0 | K11: =SUM(Paniglgasse:Lerchenfelder!K11) -> 0 | L11: =SUM(Paniglgasse:Lerchenfelder!L11) -> 0 | ... BD11: =SUM(Paniglgasse:Lerchenfelder!BD11) -> 0 | BF11: =SUM(E11:H11) -> 0 | BG11: =SUM(I11:L11) -> 0 | BH11: =SUM(M11:Q11) -> 0 | BI11: =SUM(R11:U11) -> 0 | BJ11: =SUM(V11:Y11) -> 0 | BK11: =SUM(Z11:AD11) -> 0 | BL11: =SUM(AE11:AH11) -> 0 | BM11: =SUM(AI11:AL11) -> 0 | BN11: =SUM(AM11:AQ11) -> 0 | BO11: =SUM(AR11:AU11) -> 0 | BP11: =SUM(AV11:AY11) -> 0 | BQ11: =SUM(AZ11:BD11) -> 0 | BR11: =SUM(BF11:BQ11) -> 0 | BS11: =SUM(BF11:BH11) -> 0 | BT11: =SUM(BI11:BK11) -> 0 | BU11: =SUM(BL11:BN11) -> 0 | BV11: =SUM(BO11:BQ11) -> 0 | BW11: =SUM(BF11:BK11) -> 0 | BX11: =SUM(BL11:BQ11) -> 0 | BY11: =IF(Info!$O$3="Q1",$BS11,IF(Info!$O$3="Q2",$BS11+$BT11,IF(Info!$O$3="Q3",$BS11+$BT11+$BU11,$BR11))) -> 0 | BZ11: =IF(Info!$O$3="Q1",$BS11,IF(Info!$O$3="Q2",$BT11,IF(Info!$O$3="Q3",$BU11,$BV11))) -> 0
B12: Pcs put into the shop, Handbag A new opening | D12: =SUM(E12:BD12) -> 1470.77 | E12: =SUM(Paniglgasse:Lerchenfelder!E12) -> 0 | F12: =SUM(Paniglgasse:Lerchenfelder!F12) -> 0 | G12: =SUM(Paniglgasse:Lerchenfelder!G12) -> 0 | H12: =SUM(Paniglgasse:Lerchenfelder!H12) -> 219.89 | I12: =SUM(Paniglgasse:Lerchenfelder!I12) -> 0 | J12: =SUM(Paniglgasse:Lerchenfelder!J12) -> 0 | K12: =SUM(Paniglgasse:Lerchenfelder!K12) -> 0 | L12: =SUM(Paniglgasse:Lerchenfelder!L12) -> 0 | ... BD12: =SUM(Paniglgasse:Lerchenfelder!BD12) -> 0 | BF12: =SUM(E12:H12) -> 219.89 | BG12: =SUM(I12:L12) -> 0 | BH12: =SUM(M12:Q12) -> 204.51 | BI12: =SUM(R12:U12) -> 226.5 | BJ12: =SUM(V12:Y12) -> 188.41 | BK12: =SUM(Z12:AD12) -> 178.96 | BL12: =SUM(AE12:AH12) -> 205.9 | BM12: =SUM(AI12:AL12) -> 0 | BN12: =SUM(AM12:AQ12) -> 246.6 | BO12: =SUM(AR12:AU12) -> 0 | BP12: =SUM(AV12:AY12) -> 0 | BQ12: =SUM(AZ12:BD12) -> 0 | BR12: =SUM(BF12:BQ12) -> 1470.77 | BS12: =SUM(BF12:BH12) -> 424.4 | BT12: =SUM(BI12:BK12) -> 593.87 | BU12: =SUM(BL12:BN12) -> 452.5 | BV12: =SUM(BO12:BQ12) -> 0 | BW12: =SUM(BF12:BK12) -> 1018.27 | BX12: =SUM(BL12:BQ12) -> 452.5 | BY12: =IF(Info!$O$3="Q1",$BS12,IF(Info!$O$3="Q2",$BS12+$BT12,IF(Info!$O$3="Q3",$BS12+$BT12+$BU12,$BR12))) -> 424.4 | BZ12: =IF(Info!$O$3="Q1",$BS12,IF(Info!$O$3="Q2",$BT12,IF(Info!$O$3="Q3",$BU12,$BV12))) -> 424.4
B13: Pcs put into the shop, Handbag B new opening | D13: =SUM(E13:BD13) -> 0 | E13: =SUM(Paniglgasse:Lerchenfelder!E13) -> 0 | F13: =SUM(Paniglgasse:Lerchenfelder!F13) -> 0 | G13: =SUM(Paniglgasse:Lerchenfelder!G13) -> 0 | H13: =SUM(Paniglgasse:Lerchenfelder!H13) -> 0 | I13: =SUM(Paniglgasse:Lerchenfelder!I13) -> 0 | J13: =SUM(Paniglgasse:Lerchenfelder!J13) -> 0 | K13: =SUM(Paniglgasse:Lerchenfelder!K13) -> 0 | L13: =SUM(Paniglgasse:Lerchenfelder!L13) -> 0 | ... BD13: =SUM(Paniglgasse:Lerchenfelder!BD13) -> 0 | BF13: =SUM(E13:H13) -> 0 | BG13: =SUM(I13:L13) -> 0 | BH13: =SUM(M13:Q13) -> 0 | BI13: =SUM(R13:U13) -> 0 | BJ13: =SUM(V13:Y13) -> 0 | BK13: =SUM(Z13:AD13) -> 0 | BL13: =SUM(AE13:AH13) -> 0 | BM13: =SUM(AI13:AL13) -> 0 | BN13: =SUM(AM13:AQ13) -> 0 | BO13: =SUM(AR13:AU13) -> 0 | BP13: =SUM(AV13:AY13) -> 0 | BQ13: =SUM(AZ13:BD13) -> 0 | BR13: =SUM(BF13:BQ13) -> 0 | BS13: =SUM(BF13:BH13) -> 0 | BT13: =SUM(BI13:BK13) -> 0 | BU13: =SUM(BL13:BN13) -> 0 | BV13: =SUM(BO13:BQ13) -> 0 | BW13: =SUM(BF13:BK13) -> 0 | BX13: =SUM(BL13:BQ13) -> 0 | BY13: =IF(Info!$O$3="Q1",$BS13,IF(Info!$O$3="Q2",$BS13+$BT13,IF(Info!$O$3="Q3",$BS13+$BT13+$BU13,$BR13))) -> 0 | BZ13: =IF(Info!$O$3="Q1",$BS13,IF(Info!$O$3="Q2",$BT13,IF(Info!$O$3="Q3",$BU13,$BV13))) -> 0
B14: Pcs put into the shop, things new opening | D14: =SUM(E14:BD14) -> 756.35 | E14: =SUM(Paniglgasse:Lerchenfelder!E14) -> 0 | F14: =SUM(Paniglgasse:Lerchenfelder!F14) -> 0 | G14: =SUM(Paniglgasse:Lerchenfelder!G14) -> 0 | H14: =SUM(Paniglgasse:Lerchenfelder!H14) -> 109.36 | I14: =SUM(Paniglgasse:Lerchenfelder!I14) -> 0 | J14: =SUM(Paniglgasse:Lerchenfelder!J14) -> 0 | K14: =SUM(Paniglgasse:Lerchenfelder!K14) -> 0 | L14: =SUM(Paniglgasse:Lerchenfelder!L14) -> 0 | ... BD14: =SUM(Paniglgasse:Lerchenfelder!BD14) -> 0 | BF14: =SUM(E14:H14) -> 109.36 | BG14: =SUM(I14:L14) -> 0 | BH14: =SUM(M14:Q14) -> 109.98 | BI14: =SUM(R14:U14) -> 88.22 | BJ14: =SUM(V14:Y14) -> 65.31 | BK14: =SUM(Z14:AD14) -> 121.99 | BL14: =SUM(AE14:AH14) -> 138.99 | BM14: =SUM(AI14:AL14) -> 0 | BN14: =SUM(AM14:AQ14) -> 122.5 | BO14: =SUM(AR14:AU14) -> 0 | BP14: =SUM(AV14:AY14) -> 0 | BQ14: =SUM(AZ14:BD14) -> 0 | BR14: =SUM(BF14:BQ14) -> 756.35 | BS14: =SUM(BF14:BH14) -> 219.34 | BT14: =SUM(BI14:BK14) -> 275.52 | BU14: =SUM(BL14:BN14) -> 261.49 | BV14: =SUM(BO14:BQ14) -> 0 | BW14: =SUM(BF14:BK14) -> 494.86 | BX14: =SUM(BL14:BQ14) -> 261.49 | BY14: =IF(Info!$O$3="Q1",$BS14,IF(Info!$O$3="Q2",$BS14+$BT14,IF(Info!$O$3="Q3",$BS14+$BT14+$BU14,$BR14))) -> 219.34 | BZ14: =IF(Info!$O$3="Q1",$BS14,IF(Info!$O$3="Q2",$BT14,IF(Info!$O$3="Q3",$BU14,$BV14))) -> 219.34
B15: Pcs put into the shop, total new opening | D15: =SUM(E15:BD15) -> 26938.03 | E15: =SUM(E7:E14) -> 0 | F15: =SUM(F7:F14) -> 0 | G15: =SUM(G7:G14) -> 0 | H15: =SUM(H7:H14) -> 3674.4 | I15: =SUM(I7:I14) -> 0 | J15: =SUM(J7:J14) -> 0 | K15: =SUM(K7:K14) -> 0 | L15: =SUM(L7:L14) -> 0 | ... BD15: =SUM(BD7:BD14) -> 0 | BF15: =SUM(E15:H15) -> 3674.4 | BG15: =SUM(I15:L15) -> 0 | BH15: =SUM(M15:Q15) -> 3948.89 | BI15: =SUM(R15:U15) -> 3992.56 | BJ15: =SUM(V15:Y15) -> 3840.54 | BK15: =SUM(Z15:AD15) -> 4111.24 | BL15: =SUM(AE15:AH15) -> 3707.54 | BM15: =SUM(AI15:AL15) -> 0 | BN15: =SUM(AM15:AQ15) -> 3662.86 | BO15: =SUM(AR15:AU15) -> 0 | BP15: =SUM(AV15:AY15) -> 0 | BQ15: =SUM(AZ15:BD15) -> 0 | BR15: =SUM(BF15:BQ15) -> 26938.03 | BS15: =SUM(BF15:BH15) -> 7623.29 | BT15: =SUM(BI15:BK15) -> 11944.34 | BU15: =SUM(BL15:BN15) -> 7370.4 | BV15: =SUM(BO15:BQ15) -> 0 | BW15: =SUM(BF15:BK15) -> 19567.63 | BX15: =SUM(BL15:BQ15) -> 7370.4 | BY15: =IF(Info!$O$3="Q1",$BS15,IF(Info!$O$3="Q2",$BS15+$BT15,IF(Info!$O$3="Q3",$BS15+$BT15+$BU15,$BR15))) -> 7623.29 | BZ15: =IF(Info!$O$3="Q1",$BS15,IF(Info!$O$3="Q2",$BT15,IF(Info!$O$3="Q3",$BU15,$BV15))) -> 7623.29
B16: Pcs put into the shop, shop A | D16: =SUM(E16:BD16) -> 17664.03 | E16: =SUM(Paniglgasse:Lerchenfelder!E16) -> 593.58 | F16: =SUM(Paniglgasse:Lerchenfelder!F16) -> 0 | G16: =SUM(Paniglgasse:Lerchenfelder!G16) -> 0 | H16: =SUM(Paniglgasse:Lerchenfelder!H16) -> 575.74 | I16: =SUM(Paniglgasse:Lerchenfelder!I16) -> 1153.5 | J16: =SUM(Paniglgasse:Lerchenfelder!J16) -> 219 | K16: =SUM(Paniglgasse:Lerchenfelder!K16) -> 0 | L16: =SUM(Paniglgasse:Lerchenfelder!L16) -> 0 | ... BD16: =SUM(Paniglgasse:Lerchenfelder!BD16) -> 0 | BF16: =SUM(E16:H16) -> 1169.32 | BG16: =SUM(I16:L16) -> 1372.5 | BH16: =SUM(M16:Q16) -> 2205.07 | BI16: =SUM(R16:U16) -> 1847.05 | BJ16: =SUM(V16:Y16) -> 2319.2 | BK16: =SUM(Z16:AD16) -> 2786.93 | BL16: =SUM(AE16:AH16) -> 2129.4 | BM16: =SUM(AI16:AL16) -> 1065.03 | BN16: =SUM(AM16:AQ16) -> 2769.53 | BO16: =SUM(AR16:AU16) -> 0 | BP16: =SUM(AV16:AY16) -> 0 | BQ16: =SUM(AZ16:BD16) -> 0 | BR16: =SUM(BF16:BQ16) -> 17664.03 | BS16: =SUM(BF16:BH16) -> 4746.89 | BT16: =SUM(BI16:BK16) -> 6953.18 | BU16: =SUM(BL16:BN16) -> 5963.96 | BV16: =SUM(BO16:BQ16) -> 0 | BW16: =SUM(BF16:BK16) -> 11700.07 | BX16: =SUM(BL16:BQ16) -> 5963.96 | BY16: =IF(Info!$O$3="Q1",$BS16,IF(Info!$O$3="Q2",$BS16+$BT16,IF(Info!$O$3="Q3",$BS16+$BT16+$BU16,$BR16))) -> 4746.89 | BZ16: =IF(Info!$O$3="Q1",$BS16,IF(Info!$O$3="Q2",$BT16,IF(Info!$O$3="Q3",$BU16,$BV16))) -> 4746.89
